Workbook

Sheet Model
A1: =SUM(C1:GU1) -> 1 | G1: 0.03 | K1: 0.03 | O1: 0.03 | S1: 0.02 | W1: 0.02 | AA1: 0.02 | AE1: 0.04 | AI1: 0.06 | AM1: 0.04 | AQ1: 0 | AU1: 0 | AY1: 0 | BC1: 0.01 | BG1: 0.02 | BK1: 0.02 | BO1: 0.01 | BS1: 0.02 | BW1: 0.02 | CA1: 0.01 | CE1: 0.03 | CI1: 0.04 | CM1: 0.03 | CQ1: 0.02 | CU1: 0.02 | CY1: 0.02 | DC1: 0.02 | DG1: 0.02 | DK1: 0.02 | DO1: 0 | DR1: 0 | DU1: 0 | EU1: 0 | EV1: 0.03 | EZ1: 0 | FP1: 0.02 | FT1: 0.02 | FW1: 0.02 | FZ1: 0 | GE1: 0.09 | GK1: 0.07 | GQ1: 0.05 | GU1: 0.08
B2: Odds | G2: SG: OTT | S2: Good Drive % | AE2: SG: APP | AQ2: Weighted Strokes Gained: Approach | BC2: SG: ATG | BO2: SG: Putting | CE2: Expected Hole Performance | CQ2: Birdie or Better % | DC2: Bogey Avoid | DO2: Showdown | DX2: C. History | EV2: Comps | FD2: Recent Finishes | FO2: Cut & Finish % | GC2: Form & Field Strength | GX2: Probabilities & Market Odds | HG2: Ratings | HJ2: DraftKings | HN2: FanDuel
A3: Golfer | B3: To Win | C3: Top 10 | D3: Top 20 | E3: 128 | F3: Score | G3: L3 Months | H3: Rank | I3: -0.020122075 | J3: 0.4249364 | K3: L6 Months | L3: Rank | M3: -0.060698152 | N3: 0.40605794 | O3: L18 Months | P3: Rank | Q3: -0.063892653 | R3: 0.37061702 | S3: L3 Months | T3: Rank | U3: 83.00678 | V3: 3.8468505 | W3: L6 Months | X3: Rank | Y3: 81.019672 | Z3: 3.7733022 | AA3: L18 Months | AB3: Rank | AC3: 81.200806 | AD3: 3.3441932 | AE3: L3 Months | AF3: Rank | AG3: -0.023050635 | AH3: 0.56170404 | AI3: L6 Months | AJ3: Rank | AK3: -0.087731078 | AL3: 0.48894617 | AM3: L18 Months | AN3: Rank | AO3: -0.085226087 | AP3: 0.47762592 | AQ3: L6 Months | AR3: Rank | AS3: 0 | AT3: #DIV/0! | AU3: L12 Months | AV3: Rank | AW3: 0 | AX3: #DIV/0! | AY3: L24 Months | AZ3: Rank | BA3: 0 | BB3: #DIV/0! | BC3: L3 Months | BD3: Rank | BE3: -0.0035651519 | BF3: 0.27903584 | BG3: L6 Months | BH3: Rank | BI3: -0.0026159706 | BJ3: 0.27703194 | BK3: L18 Months | BL3: Rank | BM3: -0.028962918 | BN3: 0.27789449 | BO3: L3 Months | BP3: Rank | BQ3: -0.026623631 | BR3: 0.48670008 | BS3: L6 Months | BT3: Rank | BU3: -0.045425167 | BV3: 0.38646346 | BW3: L18 Months | BX3: Rank | BY3: -0.05184611 | BZ3: 0.37457274 | CA3: Bent/Poa | CB3: Rank | CC3: -0.07390625 | CD3: 0.61237784 | CE3: L3 Months | CF3: Rank | CG3: -0.17355932 | CH3: 0.94086827 | CI3: L6 Months | CJ3: Rank | CK3: 0.17231405 | CL3: 0.54522989 | CM3: L18 Months | CN3: Rank | CO3: -0.18827869 | CP3: 0.86023795 | CQ3: L3 Months | CR3: Rank | CS3: 21.870339 | CT3: 2.4249868 | CU3: L6 Months | CV3: Rank | CW3: 20.859836 | CX3: 2.163621 | CY3: L18 Months | CZ3: Rank | DA3: 21.6368 | DB3: 1.9081524 | DC3: L3 Months | DD3: Rank | DE3: 84.840678 | DF3: 2.7145945 | DG3: L6 Months | DH3: Rank | DI3: 84.145902 | DJ3: 2.5058341 | DK3: L18 Months | DL3: Rank | DM3: 84.6608 | DN3: 2.1070509 | DO3: Ball Striking | DP3: 0 | DR3: Tee to Green | DS3: 0 | DU3: SG: Total | DV3: 0 | DX3: 2025 | DY3: 2024 | DZ3: 2023 | EA3: 2022 | EB3: 2021 | EI3: -0.5 | EJ3: 0 | EL3: 0 | EM3: 0 | EO3: 0 | EP3: 0 | ER3: 2.5 | ES3: 2.5 | ET3: 0 | EU3: Rating | EV3: Weak Field | EW3: 0.25676562 | EY3: 0.72781669 | EZ3: High Missed Fairway Penalty | FA3: 0 | FC3: 0 | FD3: Cuts Made | FE3: LW | FF3: -2W | FG3: -3W | FH3: -4W | FI3: -5W | FJ3: -6W | FK3: -7W | FL3: -8W | FM3: -9W | FN3: -10W | FO3: Events | FP3: Cut % | FR3: 0.56996805 | FS3: 0.17271913 | FT3: Top 25% Finish | FU3: 0.27617231 | FV3: 0.12837922 | FW3: Top 10% Finish | FX3: 0.11696484 | FY3: 0.070737172 | FZ3: Top 5% Finish | GA3: 0.061310791 | GB3: 0.049314269 | GC3: 1 | GD3: 2 | GE3: L3 Months SG/Round | GF3: -0.18793578 | GG3: 0.8491268 | GH3: L4 Months Rounds | GI3: L8Month SG/Round | GJ3: 2 | GK3: L8 Months SG/Round | GL3: -0.245245 | GM3: 0.67860279 | GN3: L10 Months Rounds | GO3: L12Month SG/Round | GP3: 2 | GQ3: L18 Months SG/Round | GR3: -0.14738443 | GS3: 0.61222927 | GT3: L18 Months Rounds | GU3: Field Strength | GV3: DK | GW3: FD | GX3: Win Prob | GY3: Top 5 Prob | GZ3: Top 10 Prob | HA3: Win Odds | HB3: Top 5 Odds | HC3: Top 10 Odds | HD3: Win Value | HE3: Top 5 Value | HF3: Top 10 Value | HG3: Manual Adj | HH3: Golfer Rank | HI3: Noto Rating | HJ3: Salary | HK3: pOWN% | HL3: Rank +/- | HM3: Noto Rat / $ | HN3: Salary | HO3: pOWN% | HP3: Rank +/- | HQ3: Noto Rat / $
A4: Ben Kohles | B4: 55 | C4: 550 | D4: 240 | E4: 104 | F4: 81.25 | G4: 0.3 | H4: 31 | I4: 0.75334115 | J4: 77.437753 | K4: 0.23 | L4: 30 | M4: 0.71590314 | N4: 76.297442 | O4: 0.2 | P4: 33 | Q4: 0.71203597 | R4: 76.177875 | S4: 89.8 | T4: 5 | U4: 1.7659174 | V4: 96.129515 | W4: 89.1 | X4: 2 | Y4: 2.1414473 | Z4: 98.388101 | AA4: 88.8 | AB4: 1 | AC4: 2.2723548 | AD4: 98.846746 | AE4: 0.81 | AF4: 8 | AG4: 1.4830775 | AH4: 93.097309 | AI4: 0.74 | AJ4: 2 | AK4: 1.692888 | AL4: 95.47616 | AM4: 0.81 | AN4: 1 | AO4: 1.8743248 | AP4: 96.955716 | AT4: 95.47616 | AX4: 95.47616 | BB4: 95.47616 | BC4: 0.08 | BD4: 45 | BE4: 0.2994782 | BF4: 61.77124 | BG4: 0.01 | BH4: 59 | BI4: 0.045539768 | BJ4: 51.816146 | BK4: 0.09 | BL4: 36 | BM4: 0.42808663 | BN4: 66.570598 | BO4: 0.49 | BP4: 20 | BQ4: 1.0614825 | BR4: 85.576466 | BS4: 0.22 | BT4: 35 | BU4: 0.68680534 | BV4: 75.38973 | BW4: -0.01 | BX4: 60 | BY4: 0.11171691 | BZ4: 54.447607 | CA4: -0.79 | CB4: 115 | CC4: -1.1693659 | CD4: 12.112813 | CE4: 0.8 | CF4: 15 | CG4: 1.0347456 | CH4: 84.960614 | CI4: 0.66 | CJ4: 21 | CK4: 0.8944593 | CL4: 81.44619 | CM4: 0.54 | CN4: 23 | CO4: 0.84660144 | CP4: 80.139134 | CQ4: 24.8 | CR4: 13 | CS4: 1.2081142 | CT4: 88.649833 | CU4: 23.8 | CV4: 8 | CW4: 1.358909 | CX4: 91.291228 | CY4: 23.6 | CZ4: 10 | DA4: 1.0288486 | DB4: 84.822459 | DC4: 88.9 | DD4: 5 | DE4: 1.4953696 | DF4: 93.259099 | DG4: 88 | DH4: 7 | DI4: 1.5380501 | DJ4: 93.798182 | DK4: 87.5 | DL4: 6 | DM4: 1.3474758 | DN4: 91.108647 | DQ4: 0 | DT4: 0 | DW4: 0 | DX4: #N/A | DY4: #N/A | DZ4: #N/A | EA4: #N/A | EB4: #N/A | EH4: -0.5 | EI4: #DIV/0! | EJ4: 0 | EK4: 0 | EL4: #DIV/0! | EM4: 0 | EN4: 0 | EO4: #DIV/0! | EP4: 0 | EQ4: 10 | ER4: 2.5 | ES4: #DIV/0! | ET4: 0 | EU4: 0 | EV4: 0.14 | EW4: -0.16043274 | EX4: -0.16043274 | EY4: 43.62701 | EZ4: 0 | FA4: #DIV/0! | FB4: #DIV/0! | FC4: 30 | FD4: 36/51 | FE4: 27 | FH4: 23 | FI4: 63 | FJ4: 29 | FK4: 26 | FL4: 9 | FN4: 15 | FO4: 51 | FP4: 0.70588235 | FQ4: 36 | FR4: 0.78690941 | FS4: 78.433255 | FT4: 0.47058824 | FU4: 1.5143878 | FV4: 93.503624 | FW4: 0.15686275 | FX4: 0.56403022 | FY4: 71.363322 | FZ4: 0.058823529 | GA4: -0.05043695 | GB4: 47.98871 | GC4: 1.4805751 | GD4: 0.88 | GE4: 1.1802875 | GF4: 1.6113298 | GG4: 94.644607 | GH4: 56 | GI4: 1.2400364 | GJ4: 0.4 | GK4: 0.82001819 | GL4: 1.569789 | GM4: 94.17679 | GN4: 91 | GO4: 0.69690593 | GP4: 0.23 | GQ4: 0.46345297 | GR4: 0.99772655 | GS4: 84.079401 | GT4: 171 | GU4: 32.258065 | GV4: 27 | GW4: 25 | GX4: 0.0294 | GY4: 0.15585 | GZ4: 0.29405 | HA4: 55 | HB4: 550 | HC4: 240 | HD4: 0.011542857 | HE4: 0.12481923 | HF4: 0.18841471 | HH4: =IFERROR(RANK(HI4,HI$4:HI$1100),"") -> 5 | HI4: =IFERROR(((J4*G$1)+(N4*K$1)+(R4*O$1)+(V4*S$1)+(Z4*W$1)+(AD4*AA$1)+(AH4*AE$1)+(AL4*AI$1)+(AP4*AM$1)+(AT4*AQ$1)+(AX4*AU$1)+(BB4*AY$1)+(BF4*BC$1)+(BJ4*BG$1)+(BN4*BK$1)+(BR4*BO$1)+(BV4*BS$1)+(BZ4*BW$1)+(CD4*CA$1)+(CH4*CE$1)+(CL4*CI$1)+(CP4*CM$1)+(CT4*CQ$1)+(CX4*CU$1)+(DB4*CY$1)+(DF4*DC$1)+(DJ4*DG$1)+(DN4*DK$1)+(DQ4*DO$1)+(DT4*DR$1)+(DW4*DU$1)+(EU4*EU$1)+(EY4*EV$1)+(FC4*EZ$1)+(FS4*FP$1)+(GB4*FZ$1)+(FY4*FW$1)+(FV4*FT$1)+(GG4*GE$1)+(GM4*GK$1)+(GS4*GQ$1)+(GU4*GU$1))*(1+HG4),"") -> 79.793705 | HJ4: 7700 | HK4: 0.0957 | HL4: =IFERROR(GV4-HH4,"") -> 22 | HM4: =IFERROR(HI4/(HJ4/1000),0) -> 10.362819 | HN4: 9600 | HO4: 0.1071 | HP4: =GW4-HH4 -> 20 | HQ4: =HI4/(HN4/1000) -> 8.3118443
A5: Davis Chatfield | B5: 170 | C5: 1175 | D5: 470 | E5: 55 | F5: 42.96875 | G5: -0.51 | H5: 101 | I5: -1.1528265 | J5: 12.449081 | K5: -0.44 | L5: 98 | M5: -0.9341077 | N5: 17.512417 | O5: -0.37 | P5: 99 | Q5: -0.82593979 | R5: 20.441912 | S5: 90.5 | T5: 2 | U5: 1.9478844 | V5: 97.42856 | W5: 86.1 | X5: 10 | Y5: 1.3463877 | Z5: 91.091125 | AA5: 84.4 | AB5: 19 | AC5: 0.95664136 | AD5: 83.062585 | AE5: 0.94 | AF5: 3 | AG5: 1.7145161 | AH5: 95.678301 | AI5: 0.47 | AJ5: 12 | AK5: 1.1406799 | AL5: 87.299843 | AM5: 0.22 | AN5: 33 | AO5: 0.63904841 | AP5: 73.860428 | AT5: 87.299843 | AX5: 87.299843 | BB5: 87.299843 | BC5: 0.07 | BD5: 48 | BE5: 0.26364051 | BF5: 60.397153 | BG5: -0.05 | BH5: 74 | BI5: -0.17104175 | BJ5: 43.209547 | BK5: 0.04 | BL5: 50 | BM5: 0.24816223 | BN5: 59.799556 | BO5: 0.44 | BP5: 23 | BQ5: 0.95874985 | BR5: 83.115761 | BS5: 0.32 | BT5: 25 | BU5: 0.94556202 | BV5: 82.781399 | BW5: 0.06 | BX5: 53 | BY5: 0.2985965 | BZ5: 61.737603 | CA5: -0.25 | CB5: 83 | CC5: -0.28755735 | CD5: 38.68428 | CE5: 1.99 | CF5: 2 | CG5: 2.2995348 | CH5: 98.926271 | CI5: 0.89 | CJ5: 15 | CK5: 1.3162997 | CL5: 90.596327 | CM5: 1.48 | CN5: 2 | CO5: 1.9393224 | CP5: 97.376895 | CQ5: 25.5 | CR5: 5 | CS5: 1.4967756 | CT5: 93.277417 | CU5: 21.8 | CV5: 40 | CW5: 0.43453264 | CX5: 66.804915 | CY5: 20.9 | CZ5: 89 | DA5: -0.38613267 | DB5: 34.969921 | DC5: 88.2 | DD5: 11 | DE5: 1.2375042 | DF5: 89.205002 | DG5: 86.8 | DH5: 12 | DI5: 1.0591676 | DJ5: 85.523828 | DK5: 86.2 | DL5: 24 | DM5: 0.73049969 | DN5: 76.74576 | DQ5: 0 | DT5: 0 | DW5: 0 | DX5: #N/A | DY5: #N/A | DZ5: #N/A | EA5: #N/A | EB5: #N/A | EH5: -0.5 | EI5: #DIV/0! | EJ5: 0 | EK5: 0 | EL5: #DIV/0! | EM5: 0 | EN5: 0 | EO5: #DIV/0! | EP5: 0 | EQ5: 10 | ER5: 2.5 | ES5: #DIV/0! | ET5: 0 | EU5: 0 | EV5: 0.448 | EW5: 0.26275074 | EX5: 0.26275074 | EY5: 60.362865 | EZ5: 0 | FA5: #DIV/0! | FB5: #DIV/0! | FC5: 30 | FD5: 26/44 | FJ5: 25 | FK5: MC | FL5: 16 | FM5: 34 | FN5: 5 | FO5: 44 | FP5: 0.59090909 | FQ5: 26 | FR5: 0.12124335 | FS5: 54.825085 | FT5: 0.45454545 | FU5: 1.3894238 | FV5: 91.764804 | FW5: 0.18181818 | FX5: 0.91682121 | FY5: 82.038183 | FZ5: 0.11363636 | GA5: 1.0610635 | GB5: 85.566949 | GC5: 0.81110763 | GD5: 0.51 | GE5: 0.66055381 | GF5: 0.99924957 | GG5: 84.11631 | GH5: 28 | GI5: 0.066823078 | GJ5: -0.18 | GK5: -0.056588461 | GL5: 0.27800732 | GM5: 60.949663 | GN5: 58 | GO5: 0.61829405 | GP5: -0.5 | GQ5: 0.059147024 | GR5: 0.33734332 | GS5: 63.207095 | GT5: 140 | GU5: 12.096774 | GV5: 65 | GW5: 65 | GX5: 0.0096 | GY5: 0.0655 | GZ5: 0.1394 | HA5: 170 | HB5: 1175 | HC5: 470 | HD5: 0.0037520468 | HE5: 0.05312549 | HF5: 0.089545614 | HH5: =IFERROR(RANK(HI5,HI$4:HI$1100),"") -> 22 | HI5: =IFERROR(((J5*G$1)+(N5*K$1)+(R5*O$1)+(V5*S$1)+(Z5*W$1)+(AD5*AA$1)+(AH5*AE$1)+(AL5*AI$1)+(AP5*AM$1)+(AT5*AQ$1)+(AX5*AU$1)+(BB5*AY$1)+(BF5*BC$1)+(BJ5*BG$1)+(BN5*BK$1)+(BR5*BO$1)+(BV5*BS$1)+(BZ5*BW$1)+(CD5*CA$1)+(CH5*CE$1)+(CL5*CI$1)+(CP5*CM$1)+(CT5*CQ$1)+(CX5*CU$1)+(DB5*CY$1)+(DF5*DC$1)+(DJ5*DG$1)+(DN5*DK$1)+(DQ5*DO$1)+(DT5*DR$1)+(DW5*DU$1)+(EU5*EU$1)+(EY5*EV$1)+(FC5*EZ$1)+(FS5*FP$1)+(GB5*FZ$1)+(FY5*FW$1)+(FV5*FT$1)+(GG5*GE$1)+(GM5*GK$1)+(GS5*GQ$1)+(GU5*GU$1))*(1+HG5),"") -> 66.527795 | HJ5: 6800 | HK5: 0.015 | HL5: =IFERROR(GV5-HH5,"") -> 43 | HM5: =IFERROR(HI5/(HJ5/1000),0) -> 9.7834992 | HN5: 8200 | HO5: 0.0167 | HP5: =GW5-HH5 -> 43 | HQ5: =HI5/(HN5/1000) -> 8.1131457
A6: Lee Hodges | B6: 90 | C6: 750 | D6: 320 | E6: 84 | F6: 65.625 | G6: 0.41 | H6: 17 | I6: 1.0122034 | J6: 84.42796 | K6: 0.31 | L6: 22 | M6: 0.91291936 | N6: 81.935752 | O6: 0.25 | P6: 26 | Q6: 0.84694613 | R6: 80.148742 | S6: 85.7 | T6: 31 | U6: 0.70011047 | V6: 75.807084 | W6: 83.8 | X6: 29 | Y6: 0.73684208 | Z6: 76.939081 | AA6: 83.3 | AB6: 33 | AC6: 0.62771299 | AD6: 73.490401 | AE6: 0.09 | AF6: 54 | AG6: 0.2012637 | AH6: 57.975381 | AI6: 0.12 | AJ6: 44 | AK6: 0.4248547 | AL6: 66.45287 | AM6: 0.08 | AN6: 50 | AO6: 0.34593199 | AP6: 63.530309 | AT6: 66.45287 | AX6: 66.45287 | BB6: 66.45287 | BC6: -0.18 | BD6: 94 | BE6: -0.63230174 | BF6: 26.359486 | BG6: -0.28 | BH6: 108 | BI6: -1.0012709 | BJ6: 15.834792 | BK6: -0.17 | BL6: 95 | BM6: -0.50752025 | BN6: 30.589492 | BO6: 0.38 | BP6: 29 | BQ6: 0.83547064 | BR6: 79.827362 | BS6: 0.08 | BT6: 49 | BU6: 0.324546 | BV6: 62.723765 | BW6: 0.17 | BX6: 37 | BY6: 0.59226442 | BZ6: 72.316323 | CA6: -0.03 | CB6: 65 | CC6: 0.071697974 | CD6: 52.857887 | CE6: 1.24 | CF6: 10 | CG6: 1.5023988 | CH6: 93.350292 | CI6: 0.68 | CJ6: 19 | CK6: 0.93114108 | CL6: 82.41097 | CM6: 0.93 | CN6: 14 | CO6: 1.2999644 | CP6: 90.319341 | CQ6: 24.4 | CR6: 20 | CS6: 1.0431649 | CT6: 85.156403 | CU6: 22 | CV6: 36 | CW6: 0.52697027 | CX6: 70.089288 | CY6: 22.6 | CZ6: 35 | DA6: 0.50478147 | DB6: 69.314383 | DC6: 88.3 | DD6: 9 | DE6: 1.2743421 | DF6: 89.87289 | DG6: 85.3 | DH6: 41 | DI6: 0.46056455 | DJ6: 67.744448 | DK6: 86.7 | DL6: 17 | DM6: 0.96779818 | DN6: 83.342741 | DQ6: 0 | DT6: 0 | DW6: 0 | DX6: #N/A | DY6: #N/A | DZ6: #N/A | EA6: #N/A | EB6: #N/A | EH6: -0.5 | EI6: #DIV/0! | EJ6: 0 | EK6: 0 | EL6: #DIV/0! | EM6: 0 | EN6: 0 | EO6: #DIV/0! | EP6: 0 | EQ6: 10 | ER6: 2.5 | ES6: #DIV/0! | ET6: 0 | EU6: 0 | EV6: 0.38 | EW6: 0.16932062 | EX6: 0.16932062 | EY6: 56.722777 | EZ6: 0 | FA6: #DIV/0! | FB6: #DIV/0! | FC6: 30 | FD6: 27/42 | FJ6: 72 | FK6: MC | FL6: 20 | FN6: MC | FO6: 42 | FP6: 0.64285714 | FQ6: 27 | FR6: 0.42200941 | FS6: 66.349093 | FT6: 0.30952381 | FU6: 0.2597889 | FV6: 60.248669 | FW6: 0.16666667 | FX6: 0.70262668 | FY6: 75.885578 | FZ6: 0.047619048 | GA6: -0.27764263 | GB6: 39.064335 | GC6: 0.58370919 | GD6: 0.42 | GE6: 0.50185459 | GF6: 0.81235261 | GG6: 79.170533 | GH6: 24 | GI6: 0.29236502 | GJ6: 0.14 | GK6: 0.21618251 | GL6: 0.67996702 | GM6: 75.173733 | GN6: 59 | GO6: 0.36853179 | GP6: 0.09 | GQ6: 0.2292659 | GR6: 0.61521124 | GS6: 73.079239 | GT6: 139 | GU6: 66.129032 | GV6: 39 | GW6: 43 | GX6: 0.0174 | GY6: 0.0965 | GZ6: 0.19115 | HA6: 90 | HB6: 750 | HC6: 320 | HD6: 0.006410989 | HE6: 0.061738235 | HF6: 0.099140476 | HH6: =IFERROR(RANK(HI6,HI$4:HI$1100),"") -> 15 | HI6: =IFERROR(((J6*G$1)+(N6*K$1)+(R6*O$1)+(V6*S$1)+(Z6*W$1)+(AD6*AA$1)+(AH6*AE$1)+(AL6*AI$1)+(AP6*AM$1)+(AT6*AQ$1)+(AX6*AU$1)+(BB6*AY$1)+(BF6*BC$1)+(BJ6*BG$1)+(BN6*BK$1)+(BR6*BO$1)+(BV6*BS$1)+(BZ6*BW$1)+(CD6*CA$1)+(CH6*CE$1)+(CL6*CI$1)+(CP6*CM$1)+(CT6*CQ$1)+(CX6*CU$1)+(DB6*CY$1)+(DF6*DC$1)+(DJ6*DG$1)+(DN6*DK$1)+(DQ6*DO$1)+(DT6*DR$1)+(DW6*DU$1)+(EU6*EU$1)+(EY6*EV$1)+(FC6*EZ$1)+(FS6*FP$1)+(GB6*FZ$1)+(FY6*FW$1)+(FV6*FT$1)+(GG6*GE$1)+(GM6*GK$1)+(GS6*GQ$1)+(GU6*GU$1))*(1+HG6),"") -> 71.187314 | HJ6: 7300 | HK6: 0.0391 | HL6: =IFERROR(GV6-HH6,"") -> 24 | HM6: =IFERROR(HI6/(HJ6/1000),0) -> 9.7516869 | HN6: 8800 | HO6: 0.0311 | HP6: =GW6-HH6 -> 28 | HQ6: =HI6/(HN6/1000) -> 8.0894675
A7: Zac Blair | B7: 80 | C7: 750 | D7: 320 | E7: 88 | F7: 68.75 | G7: -0.64 | H7: 105 | I7: -1.4587546 | J7: 7.2316332 | K7: -0.52 | L7: 107 | M7: -1.1311239 | N7: 12.900147 | O7: -0.33 | P7: 96 | Q7: -0.71801167 | R7: 23.637505 | S7: 85.1 | T7: 43 | U7: 0.54413872 | V7: 70.682699 | W7: 84.6 | X7: 20 | Y7: 0.94885796 | Z7: 82.865357 | AA7: 86.5 | AB7: 5 | AC7: 1.5845955 | AD7: 94.347087 | AE7: 0.77 | AF7: 10 | AG7: 1.4118656 | AH7: 92.100524 | AI7: 0.6 | AJ7: 4 | AK7: 1.4065579 | AL7: 92.022073 | AM7: 0.76 | AN7: 2 | AO7: 1.7696403 | AP7: 96.160646 | AT7: 92.022073 | AX7: 92.022073 | BB7: 92.022073 | BC7: 0.36 | BD7: 11 | BE7: 1.3029335 | BF7: 90.370127 | BG7: 0.13 | BH7: 33 | BI7: 0.47870281 | BJ7: 68.392497 | BK7: 0.04 | BL7: 50 | BM7: 0.24816223 | BN7: 59.799556 | BO7: 0.87 | BP7: 3 | BQ7: 1.8422508 | BR7: 96.728077 | BS7: 0.34 | BT7: 24 | BU7: 0.99731336 | BV7: 84.069378 | BW7: 0.13 | BX7: 46 | BY7: 0.48547609 | BZ7: 68.633066 | CA7: 0.44 | CB7: 20 | CC7: 0.83919799 | CD7: 79.932089 | CE7: -0.04 | CF7: 58 | CG7: 0.14195326 | CH7: 55.644154 | CI7: -0.28 | CJ7: 98 | CK7: -0.8295841 | CL7: 20.338699 | CM7: -0.49 | CN7: 80 | CO7: -0.35074169 | CP7: 36.289107 | CQ7: 22.7 | CR7: 45 | CS7: 0.34213012 | CT7: 63.387351 | CU7: 21.9 | CV7: 37 | CW7: 0.48075146 | CX7: 68.465342 | CY7: 23.4 | CZ7: 18 | DA7: 0.92403519 | DB7: 82.2266 | DC7: 88.1 | DD7: 12 | DE7: 1.2006663 | DF7: 88.505966 | DG7: 85.9 | DH7: 27 | DI7: 0.70000578 | DJ7: 75.803815 | DK7: 86.6 | DL7: 18 | DM7: 0.92033848 | DN7: 82.130205 | DQ7: 0 | DT7: 0 | DW7: 0 | DX7: #N/A | DY7: #N/A | DZ7: #N/A | EA7: #N/A | EB7: #N/A | EH7: -0.5 | EI7: #DIV/0! | EJ7: 0 | EK7: 0 | EL7: #DIV/0! | EM7: 0 | EN7: 0 | EO7: #DIV/0! | EP7: 0 | EQ7: 10 | ER7: 2.5 | ES7: #DIV/0! | ET7: 0 | EU7: 0 | EV7: 0.44 | EW7: 0.25175896 | EX7: 0.25175896 | EY7: 59.938631 | EZ7: 0 | FA7: #DIV/0! | FB7: #DIV/0! | FC7: 30 | FD7: 30/46 | FE7: MC | FH7: MC | FI7: 4 | FJ7: MC | FK7: 50 | FL7: 13 | FN7: 8 | FO7: 46 | FP7: 0.65217391 | FQ7: 30 | FR7: 0.47595115 | FS7: 68.294541 | FT7: 0.39130435 | FU7: 0.89681206 | FV7: 81.50904 | FW7: 0.19565217 | FX7: 1.1123901 | FY7: 86.701478 | FZ7: 0.065217391 | GA7: 0.079218462 | GB7: 53.157057 | GC7: 1.22558 | GD7: 0.83 | GE7: 1.02779 | GF7: 1.4317364 | GG7: 92.389037 | GH7: 48 | GI7: 1.043823 | GJ7: 0.28 | GK7: 0.66191149 | GL7: 1.3368004 | GM7: 90.93561 | GN7: 84 | GO7: 0.6939892 | GP7: 0.26 | GQ7: 0.4769946 | GR7: 1.0198451 | GS7: 84.609904 | GT7: 153 | GU7: 26.612903 | GV7: 39 | GW7: 49 | GX7: 0.01305 | GY7: 0.0767 | GZ7: 0.1628 | HA7: 80 | HB7: 750 | HC7: 320 | HD7: 0.00070432099 | HE7: 0.033388235 | HF7: 0.050140476 | HH7: =IFERROR(RANK(HI7,HI$4:HI$1100),"") -> 20 | HI7: =IFERROR(((J7*G$1)+(N7*K$1)+(R7*O$1)+(V7*S$1)+(Z7*W$1)+(AD7*AA$1)+(AH7*AE$1)+(AL7*AI$1)+(AP7*AM$1)+(AT7*AQ$1)+(AX7*AU$1)+(BB7*AY$1)+(BF7*BC$1)+(BJ7*BG$1)+(BN7*BK$1)+(BR7*BO$1)+(BV7*BS$1)+(BZ7*BW$1)+(CD7*CA$1)+(CH7*CE$1)+(CL7*CI$1)+(CP7*CM$1)+(CT7*CQ$1)+(CX7*CU$1)+(DB7*CY$1)+(DF7*DC$1)+(DJ7*DG$1)+(DN7*DK$1)+(DQ7*DO$1)+(DT7*DR$1)+(DW7*DU$1)+(EU7*EU$1)+(EY7*EV$1)+(FC7*EZ$1)+(FS7*FP$1)+(GB7*FZ$1)+(FY7*FW$1)+(FV7*FT$1)+(GG7*GE$1)+(GM7*GK$1)+(GS7*GQ$1)+(GU7*GU$1))*(1+HG7),"") -> 67.96117 | HJ7: 7300 | HK7: 0.1074 | HL7: =IFERROR(GV7-HH7,"") -> 19 | HM7: =IFERROR(HI7/(HJ7/1000),0) -> 9.3097494 | HN7: 8600 | HO7: 0.1265 | HP7: =GW7-HH7 -> 29 | HQ7: =HI7/(HN7/1000) -> 7.9024617
A8: Zachary Bauchou | B8: 66 | C8: 700 | D8: 250 | E8: 92 | F8: 71.875 | G8: 0.05 | H8: 57 | I8: 0.16501781 | J8: 56.553502 | K8: 0.07 | L8: 51 | M8: 0.3218707 | N8: 62.622467 | O8: -0.07 | P8: 65 | Q8: -0.016478864 | R8: 49.342618 | S8: 81 | T8: 75 | U8: -0.52166822 | V8: 30.095068 | W8: 80.3 | X8: 71 | Y8: -0.1907274 | Z8: 42.436958 | AA8: 79.6 | AB8: 88 | AC8: -0.4786824 | AD8: 31.608229 | AE8: 0.08 | AF8: 55 | AG8: 0.18346073 | AH8: 57.278174 | AI8: 0.26 | AJ8: 27 | AK8: 0.71118479 | AL8: 76.151513 | AM8: 0.26 | AN8: 25 | AO8: 0.72279596 | AP8: 76.509738 | AT8: 76.151513 | AX8: 76.151513 | BB8: 76.151513 | BC8: -0.17 | BD8: 92 | BE8: -0.59646405 | BF8: 27.543263 | BG8: 0.04 | BH8: 53 | BI8: 0.15383053 | BJ8: 56.112832 | BK8: 0.08 | BL8: 43 | BM8: 0.39210175 | BN8: 65.250848 | BO8: 0.55 | BP8: 14 | BQ8: 1.1847617 | BR8: 88.194417 | BS8: 0.25 | BT8: 28 | BU8: 0.76443235 | BV8: 77.769518 | BW8: 0.21 | BX8: 33 | BY8: 0.69905276 | BZ8: 75.774047 | CA8: -0.16 | CB8: 76 | CC8: -0.14058926 | CD8: 44.409721 | CE8: 1.38 | CF8: 7 | CG8: 1.6511975 | CH8: 95.065087 | CI8: 1.05 | CJ8: 10 | CK8: 1.6097539 | CL8: 94.62742 | CM8: 0.95 | CN8: 12 | CO8: 1.3232138 | CP8: 90.711785 | CQ8: 25.3 | CR8: 7 | CS8: 1.4143009 | CT8: 92.136322 | CU8: 23.9 | CV8: 7 | CW8: 1.4051278 | CX8: 92.000836 | CY8: 23.5 | CZ8: 15 | DA8: 0.9764419 | DB8: 83.557724 | DC8: 86.6 | DD8: 32 | DE8: 0.64809755 | DF8: 74.153907 | DG8: 86.1 | DH8: 19 | DI8: 0.77981953 | DJ8: 78.225144 | DK8: 86.3 | DL8: 22 | DM8: 0.77795939 | DN8: 78.170352 | DQ8: 0 | DT8: 0 | DW8: 0 | DX8: #N/A | DY8: #N/A | DZ8: #N/A | EA8: #N/A | EB8: #N/A | EH8: -0.5 | EI8: #DIV/0! | EJ8: 0 | EK8: 0 | EL8: #DIV/0! | EM8: 0 | EN8: 0 | EO8: #DIV/0! | EP8: 0 | EQ8: 10 | ER8: 2.5 | ES8: #DIV/0! | ET8: 0 | EU8: 0 | EV8: 0.648 | EW8: 0.53754521 | EX8: 0.53754521 | EY8: 70.455447 | EZ8: 0 | FA8: #DIV/0! | FB8: #DIV/0! | FC8: 30 | FD8: 31/45 | FJ8: 14 | FK8: MC | FL8: 44 | FM8: 9 | FN8: MC | FO8: 45 | FP8: 0.68888889 | FQ8: 31 | FR8: 0.68852156 | FS8: 75.44378 | FT8: 0.46666667 | FU8: 1.483841 | FV8: 93.107445 | FW8: 0.22222222 | FX8: 1.4880066 | FY8: 93.162543 | FZ8: 0.11111111 | GA8: 1.0098562 | GB8: 84.371791 | GC8: 0.91785696 | GD8: 0.18 | GE8: 0.54892848 | GF8: 0.8677906 | GG8: 80.724551 | GH8: 30 | GI8: 0.68065907 | GJ8: 0.59 | GK8: 0.63532954 | GL8: 1.2976288 | GM8: 90.279254 | GN8: 74 | GO8: 0.75308123 | GP8: 0.31 | GQ8: 0.53154061 | GR8: 1.1089392 | GS8: 86.62718 | GT8: 155 | GU8: 18.548387 | GV8: 32 | GW8: 37 | GX8: 0.0137 | GY8: 0.084 | GZ8: 0.1785 | HA8: 66 | HB8: 700 | HC8: 250 | HD8: -0.0012253731 | HE8: 0.041 | HF8: 0.024628571 | HH8: =IFERROR(RANK(HI8,HI$4:HI$1100),"") -> 17 | HI8: =IFERROR(((J8*G$1)+(N8*K$1)+(R8*O$1)+(V8*S$1)+(Z8*W$1)+(AD8*AA$1)+(AH8*AE$1)+(AL8*AI$1)+(AP8*AM$1)+(AT8*AQ$1)+(AX8*AU$1)+(BB8*AY$1)+(BF8*BC$1)+(BJ8*BG$1)+(BN8*BK$1)+(BR8*BO$1)+(BV8*BS$1)+(BZ8*BW$1)+(CD8*CA$1)+(CH8*CE$1)+(CL8*CI$1)+(CP8*CM$1)+(CT8*CQ$1)+(CX8*CU$1)+(DB8*CY$1)+(DF8*DC$1)+(DJ8*DG$1)+(DN8*DK$1)+(DQ8*DO$1)+(DT8*DR$1)+(DW8*DU$1)+(EU8*EU$1)+(EY8*EV$1)+(FC8*EZ$1)+(FS8*FP$1)+(GB8*FZ$1)+(FY8*FW$1)+(FV8*FT$1)+(GG8*GE$1)+(GM8*GK$1)+(GS8*GQ$1)+(GU8*GU$1))*(1+HG8),"") -> 70.229804 | HJ8: 7500 | HK8: 0.0994 | HL8: =IFERROR(GV8-HH8,"") -> 15 | HM8: =IFERROR(HI8/(HJ8/1000),0) -> 9.3639738 | HN8: 9000 | HO8: 0.0666 | HP8: =GW8-HH8 -> 20 | HQ8: =HI8/(HN8/1000) -> 7.8033115
A9: Jackson Suber | B9: 45 | C9: 500 | D9: 230 | E9: 112 | F9: 87.5 | G9: 0.28 | H9: 37 | I9: 0.70627528 | J9: 75.999152 | K9: 0.21 | L9: 34 | M9: 0.66664908 | N9: 74.750185 | O9: 0.12 | P9: 43 | Q9: 0.49617972 | R9: 69.011619 | S9: 86.3 | T9: 25 | U9: 0.85608222 | V9: 80.402385 | W9: 85.2 | X9: 13 | Y9: 1.1078699 | Z9: 86.604099 | AA9: 84.7 | AB9: 17 | AC9: 1.0463491 | AD9: 85.230006 | AE9: 0.43 | AF9: 24 | AG9: 0.80656467 | AH9: 79.004133 | AI9: 0.52 | AJ9: 9 | AK9: 1.2429407 | AL9: 89.305515 | AM9: 0.3 | AN9: 21 | AO9: 0.80654351 | AP9: 79.003523 | AT9: 89.305515 | AX9: 89.305515 | BB9: 89.305515 | BC9: 0.39 | BD9: 8 | BE9: 1.4104466 | BF9: 92.079607 | BG9: 0.23 | BH9: 16 | BI9: 0.83967201 | BJ9: 79.945385 | BK9: 0.05 | BL9: 46 | BM9: 0.28414711 | BN9: 61.185118 | BO9: -0.04 | BP9: 62 | BQ9: -0.027483802 | BR9: 48.903693 | BS9: -0.12 | BT9: 71 | BU9: -0.19296736 | BV9: 42.349227 | BW9: -0.07 | BX9: 65 | BY9: -0.048465592 | BZ9: 48.067259 | CA9: 0.58 | CB9: 16 | CC9: 1.067815 | CD9: 85.719802 | CE9: 2.06 | CF9: 1 | CG9: 2.3739342 | CH9: 99.120016 | CI9: 1.67 | CJ9: 1 | CK9: 2.7468889 | CL9: 99.699182 | CM9: 1.37 | CN9: 4 | CO9: 1.8114508 | CP9: 96.496445 | CQ9: 25.2 | CR9: 8 | CS9: 1.3730636 | CT9: 91.513371 | CU9: 24.3 | CV9: 4 | CW9: 1.590003 | CX9: 94.408294 | CY9: 24.1 | CZ9: 5 | DA9: 1.2908822 | DB9: 90.162773 | DC9: 85.9 | DD9: 44 | DE9: 0.39023215 | DF9: 65.181755 | DG9: 86 | DH9: 24 | DI9: 0.73991266 | DJ9: 77.03235 | DK9: 85.9 | DL9: 33 | DM9: 0.58812059 | DN9: 72.177432 | DQ9: 0 | DT9: 0 | DW9: 0 | DX9: #N/A | DY9: #N/A | DZ9: #N/A | EA9: #N/A | EB9: #N/A | EH9: -0.5 | EI9: #DIV/0! | EJ9: 0 | EK9: 0 | EL9: #DIV/0! | EM9: 0 | EN9: 0 | EO9: #DIV/0! | EP9: 0 | EQ9: 10 | ER9: 2.5 | ES9: #DIV/0! | ET9: 0 | EU9: 0 | EV9: 0.19 | EW9: -0.091734122 | EX9: -0.091734122 | EY9: 46.345464 | EZ9: 0 | FA9: #DIV/0! | FB9: #DIV/0! | FC9: 30 | FD9: 26/46 | FJ9: 22 | FK9: 50 | FL9: MC | FM9: 28 | FO9: 46 | FP9: 0.56521739 | FQ9: 26 | FR9: -0.027505085 | FS9: 48.902844 | FT9: 0.30434783 | FU9: 0.21947098 | FV9: 58.685841 | FW9: 0.17391304 | FX9: 0.80506754 | FY9: 78.960965 | FZ9: 0.15217391 | GA9: 1.8425321 | GB9: 96.730132 | GC9: 1.0551821 | GD9: 1.13 | GE9: 1.0925911 | GF9: 1.5080514 | GG9: 93.422931 | GH9: 36 | GI9: 0.3637498 | GJ9: 0.73 | GK9: 0.5468749 | GL9: 1.1672806 | GM9: 87.845147 | GN9: 67 | GO9: 0.24033682 | GP9: 0.13 | GQ9: 0.18516841 | GR9: 0.5431835 | GS9: 70.649827 | GT9: 146 | GU9: 54.83871 | GV9: 19 | GW9: 18 | GX9: 0.0525 | GY9: 0.1877 | GZ9: 0.3072 | HA9: 45 | HB9: 500 | HC9: 230 | HD9: 0.03076087 | HE9: 0.12386667 | HF9: 0.14111515 | HH9: =IFERROR(RANK(HI9,HI$4:HI$1100),"") -> 7 | HI9: =IFERROR(((J9*G$1)+(N9*K$1)+(R9*O$1)+(V9*S$1)+(Z9*W$1)+(AD9*AA$1)+(AH9*AE$1)+(AL9*AI$1)+(AP9*AM$1)+(AT9*AQ$1)+(AX9*AU$1)+(BB9*AY$1)+(BF9*BC$1)+(BJ9*BG$1)+(BN9*BK$1)+(BR9*BO$1)+(BV9*BS$1)+(BZ9*BW$1)+(CD9*CA$1)+(CH9*CE$1)+(CL9*CI$1)+(CP9*CM$1)+(CT9*CQ$1)+(CX9*CU$1)+(DB9*CY$1)+(DF9*DC$1)+(DJ9*DG$1)+(DN9*DK$1)+(DQ9*DO$1)+(DT9*DR$1)+(DW9*DU$1)+(EU9*EU$1)+(EY9*EV$1)+(FC9*EZ$1)+(FS9*FP$1)+(GB9*FZ$1)+(FY9*FW$1)+(FV9*FT$1)+(GG9*GE$1)+(GM9*GK$1)+(GS9*GQ$1)+(GU9*GU$1))*(1+HG9),"") -> 77.478316 | HJ9: 8200 | HK9: 0.172 | HL9: =IFERROR(GV9-HH9,"") -> 12 | HM9: =IFERROR(HI9/(HJ9/1000),0) -> 9.4485751 | HN9: 10000 | HO9: 0.1664 | HP9: =GW9-HH9 -> 11 | HQ9: =HI9/(HN9/1000) -> 7.7478316
A10: Emiliano Grillo | B10: 60 | C10: 550 | D10: 240 | E10: 101 | F10: 78.90625 | G10: 0.32 | H10: 28 | I10: 0.80040701 | J10: 78.826249 | K10: 0.18 | L10: 38 | M10: 0.592768 | N10: 72.333179 | O10: 0.11 | P10: 44 | Q10: 0.46919769 | R10: 68.053583 | S10: 85.7 | T10: 31 | U10: 0.70011047 | V10: 75.807084 | W10: 83.5 | X10: 33 | Y10: 0.65733613 | Z10: 74.451759 | AA10: 83.9 | AB10: 25 | AC10: 0.80712846 | AD10: 79.020376 | AE10: 0.45 | AF10: 22 | AG10: 0.84217061 | AH10: 80.015377 | AI10: 0.21 | AJ10: 35 | AK10: 0.60892405 | AL10: 72.871261 | AM10: 0.26 | AN10: 25 | AO10: 0.72279596 | AP10: 76.509738 | AT10: 72.871261 | AX10: 72.871261 | BB10: 72.871261 | BC10: -0.01 | BD10: 67 | BE10: -0.023061009 | BF10: 49.08008 | BG10: -0.06 | BH10: 76 | BI10: -0.20713867 | BJ10: 41.795078 | BK10: -0.14 | BL10: 88 | BM10: -0.39956561 | BN10: 34.473825 | BO10: 0.7 | BP10: 4 | BQ10: 1.4929597 | BR10: 93.227614 | BS10: -0.02 | BT10: 58 | BU10: 0.065789318 | BV10: 52.622722 | BW10: -0.06 | BX10: 64 | BY10: -0.021768508 | BZ10: 49.131631 | CA10: 0.43 | CB10: 21 | CC10: 0.8228682 | CD10: 79.470853 | CE10: 0.49 | CF10: 26 | CG10: 0.70526273 | CH10: 75.967663 | CI10: 0.62 | CJ10: 24 | CK10: 0.82109575 | CL10: 79.420414 | CM10: 0.24 | CN10: 40 | CO10: 0.49786072 | CP10: 69.070889 | CQ10: 24.7 | CR10: 15 | CS10: 1.1668769 | CT10: 87.836995 | CU10: 22.5 | CV10: 23 | CW10: 0.75806435 | CX10: 77.579377 | CY10: 23 | CZ10: 24 | DA10: 0.71440833 | DB10: 76.251264 | DC10: 86.6 | DD10: 32 | DE10: 0.64809755 | DF10: 74.153907 | DG10: 83.1 | DH10: 85 | DI10: -0.41738663 | DJ10: 33.819782 | DK10: 84.5 | DL10: 66 | DM10: -0.076315196 | DN10: 46.958417 | DQ10: 0 | DT10: 0 | DW10: 0 | DX10: #N/A | DY10: #N/A | DZ10: #N/A | EA10: #N/A | EB10: #N/A | EH10: -0.5 | EI10: #DIV/0! | EJ10: 0 | EK10: 0 | EL10: #DIV/0! | EM10: 0 | EN10: 0 | EO10: #DIV/0! | EP10: 0 | EQ10: 10 | ER10: 2.5 | ES10: #DIV/0! | ET10: 0 | EU10: 0 | EV10: 0.73 | EW10: 0.65021094 | EX10: 0.65021094 | EY10: 74.222201 | EZ10: 0 | FA10: #DIV/0! | FB10: #DIV/0! | FC10: 30 | FD10: 32/47 | FJ10: MC | FK10: 31 | FL10: 7 | FO10: 47 | FP10: 0.68085106 | FQ10: 32 | FR10: 0.64198459 | FS10: 73.95584 | FT10: 0.31914894 | FU10: 0.33476308 | FV10: 63.109809 | FW10: 0.085106383 | FX10: -0.45037791 | FY10: 32.621898 | FZ10: 0.063829787 | GA10: 0.051080479 | GB10: 52.03693 | GC10: 1.0196998 | GD10: 1.36 | GE10: 1.1898499 | GF10: 1.6225912 | GG10: 94.766159 | GH10: 32 | GI10: 0.023649662 | GJ10: 0.21 | GK10: 0.11682483 | GL10: 0.53355194 | GM10: 70.317422 | GN10: 65 | GO10: 0.23894264 | GP10: 0.14 | GQ10: 0.18947132 | GR10: 0.55021177 | GS10: 70.891293 | GT10: 156 | GU10: 76.612903 | GV10: 35 | GW10: 31 | GX10: 0.0283 | GY10: 0.12385 | GZ10: 0.2253 | HA10: 60 | HB10: 550 | HC10: 240 | HD10: 0.011906557 | HE10: 0.056069231 | HF10: 0.063364706 | HH10: =IFERROR(RANK(HI10,HI$4:HI$1100),"") -> 14 | HI10: =IFERROR(((J10*G$1)+(N10*K$1)+(R10*O$1)+(V10*S$1)+(Z10*W$1)+(AD10*AA$1)+(AH10*AE$1)+(AL10*AI$1)+(AP10*AM$1)+(AT10*AQ$1)+(AX10*AU$1)+(BB10*AY$1)+(BF10*BC$1)+(BJ10*BG$1)+(BN10*BK$1)+(BR10*BO$1)+(BV10*BS$1)+(BZ10*BW$1)+(CD10*CA$1)+(CH10*CE$1)+(CL10*CI$1)+(CP10*CM$1)+(CT10*CQ$1)+(CX10*CU$1)+(DB10*CY$1)+(DF10*DC$1)+(DJ10*DG$1)+(DN10*DK$1)+(DQ10*DO$1)+(DT10*DR$1)+(DW10*DU$1)+(EU10*EU$1)+(EY10*EV$1)+(FC10*EZ$1)+(FS10*FP$1)+(GB10*FZ$1)+(FY10*FW$1)+(FV10*FT$1)+(GG10*GE$1)+(GM10*GK$1)+(GS10*GQ$1)+(GU10*GU$1))*(1+HG10),"") -> 71.778661 | HJ10: 7400 | HK10: 0.0737 | HL10: =IFERROR(GV10-HH10,"") -> 21 | HM10: =IFERROR(HI10/(HJ10/1000),0) -> 9.6998191 | HN10: 9300 | HO10: 0.0645 | HP10: =GW10-HH10 -> 17 | HQ10: =HI10/(HN10/1000) -> 7.7181356
A11: Christiaan Bezuidenhout | B11: 50 | C11: 500 | D11: 230 | E11: 108 | F11: 84.375 | G11: -0.32 | H11: 92 | I11: -0.70570072 | J11: 24.018714 | K11: -0.34 | L11: 92 | M11: -0.68783743 | N11: 24.577758 | O11: -0.32 | P11: 95 | Q11: -0.69102964 | R11: 24.477346 | S11: 85.7 | T11: 31 | U11: 0.70011047 | V11: 75.807084 | W11: 82.2 | X11: 48 | Y11: 0.31281032 | Z11: 62.278761 | AA11: 82.1 | AB11: 52 | AC11: 0.26888205 | AD11: 60.598978 | AE11: 0.71 | AF11: 13 | AG11: 1.3050478 | AH11: 90.406172 | AI11: 0.43 | AJ11: 16 | AK11: 1.0588713 | AL11: 85.517081 | AM11: 0.42 | AN11: 10 | AO11: 1.0577862 | AP11: 85.492353 | AT11: 85.517081 | AX11: 85.517081 | BB11: 85.517081 | BC11: 0.06 | BD11: 51 | BE11: 0.22780282 | BF11: 59.010023 | BG11: 0.18 | BH11: 24 | BI11: 0.65918741 | BJ11: 74.511229 | BK11: 0.27 | BL11: 13 | BM11: 1.0758145 | BN11: 85.899488 | BO11: 0.31 | BP11: 34 | BQ11: 0.6916449 | BR11: 75.541982 | BS11: 0.41 | BT11: 17 | BU11: 1.178443 | BV11: 88.068998 | BW11: 0.45 | BX11: 9 | BY11: 1.3397828 | BZ11: 90.984201 | CA11: 0.38 | CB11: 26 | CC11: 0.74121926 | CD11: 77.071975 | CE11: 0.58 | CF11: 22 | CG11: 0.80091905 | CH11: 78.841075 | CI11: 0.73 | CJ11: 18 | CK11: 1.0228455 | CL11: 84.680955 | CM11: 0.7 | CN11: 19 | CO11: 1.0325965 | CP11: 84.910361 | CQ11: 23.2 | CR11: 36 | CS11: 0.54831681 | CT11: 70.826281 | CU11: 21.8 | CV11: 40 | CW11: 0.43453264 | CX11: 66.804915 | CY11: 22.5 | CZ11: 42 | DA11: 0.45237476 | DB11: 67.450049 | DC11: 88.7 | DD11: 7 | DE11: 1.4216938 | DF11: 92.244241 | DG11: 87 | DH11: 10 | DI11: 1.1389814 | DJ11: 87.264454 | DK11: 87.9 | DL11: 4 | DM11: 1.5373146 | DN11: 93.789185 | DQ11: 0 | DT11: 0 | DW11: 0 | DX11: #N/A | DY11: #N/A | DZ11: #N/A | EA11: #N/A | EB11: #N/A | EH11: -0.5 | EI11: #DIV/0! | EJ11: 0 | EK11: 0 | EL11: #DIV/0! | EM11: 0 | EN11: 0 | EO11: #DIV/0! | EP11: 0 | EQ11: 10 | ER11: 2.5 | ES11: #DIV/0! | ET11: 0 | EU11: 0 | EV11: 1.19 | EW11: 1.2822382 | EX11: 1.2822382 | EY11: 90.012045 | EZ11: 0 | FA11: #DIV/0! | FB11: #DIV/0! | FC11: 30 | FD11: 40/50 | FJ11: 38 | FK11: 45 | FL11: 20 | FM11: 69 | FN11: 21 | FO11: 50 | FP11: 0.8 | FQ11: 40 | FR11: 1.3318267 | FS11: 90.854144 | FT11: 0.42 | FU11: 1.1203346 | FV11: 86.87144 | FW11: 0.18 | FX11: 0.89111786 | FY11: 81.356703 | FZ11: 0.06 | GA11: -0.026580354 | GB11: 48.939722 | GC11: 0.83982312 | GD11: 0.41 | GE11: 0.62491156 | GF11: 0.95727439 | GG11: 83.078561 | GH11: 38 | GI11: 0.80132126 | GJ11: 0.4 | GK11: 0.60066063 | GL11: 1.2465402 | GM11: 89.371692 | GN11: 78 | GO11: 0.69822174 | GP11: 0.68 | GQ11: 0.68911087 | GR11: 1.3663105 | GS11: 91.407924 | GT11: 181 | GU11: 79.032258 | GV11: 20 | GW11: 17 | GX11: 0.02055 | GY11: 0.12755 | GZ11: 0.25835 | HA11: 50 | HB11: 500 | HC11: 230 | HD11: 0.00094215686 | HE11: 0.075016667 | HF11: 0.14066515 | HH11: =IFERROR(RANK(HI11,HI$4:HI$1100),"") -> 6 | HI11: =IFERROR(((J11*G$1)+(N11*K$1)+(R11*O$1)+(V11*S$1)+(Z11*W$1)+(AD11*AA$1)+(AH11*AE$1)+(AL11*AI$1)+(AP11*AM$1)+(AT11*AQ$1)+(AX11*AU$1)+(BB11*AY$1)+(BF11*BC$1)+(BJ11*BG$1)+(BN11*BK$1)+(BR11*BO$1)+(BV11*BS$1)+(BZ11*BW$1)+(CD11*CA$1)+(CH11*CE$1)+(CL11*CI$1)+(CP11*CM$1)+(CT11*CQ$1)+(CX11*CU$1)+(DB11*CY$1)+(DF11*DC$1)+(DJ11*DG$1)+(DN11*DK$1)+(DQ11*DO$1)+(DT11*DR$1)+(DW11*DU$1)+(EU11*EU$1)+(EY11*EV$1)+(FC11*EZ$1)+(FS11*FP$1)+(GB11*FZ$1)+(FY11*FW$1)+(FV11*FT$1)+(GG11*GE$1)+(GM11*GK$1)+(GS11*GQ$1)+(GU11*GU$1))*(1+HG11),"") -> 77.613832 | HJ11: 8100 | HK11: 0.0668 | HL11: =IFERROR(GV11-HH11,"") -> 14 | HM11: =IFERROR(HI11/(HJ11/1000),0) -> 9.5819545 | HN11: 10100 | HO11: 0.0891 | HP11: =GW11-HH11 -> 11 | HQ11: =HI11/(HN11/1000) -> 7.6845378
A12: Blades Brown | B12: 40 | C12: 475 | D12: 210 | E12: 113 | F12: 88.28125 | G12: 0.39 | H12: 20 | I12: 0.96513755 | J12: 83.276204 | K12: 0.28 | L12: 23 | M12: 0.83903827 | N12: 79.927608 | O12: 0.17 | P12: 37 | Q12: 0.63108988 | R12: 73.600912 | S12: 90.7 | T12: 1 | U12: 1.999875 | V12: 97.724312 | W12: 85.2 | X12: 13 | Y12: 1.1078699 | Z12: 86.604099 | AA12: 84.8 | AB12: 16 | AC12: 1.0762517 | AD12: 85.909264 | AE12: 0.72 | AF12: 12 | AG12: 1.3228508 | AH12: 90.70575 | AI12: 0.94 | AJ12: 1 | AK12: 2.1019309 | AL12: 98.222034 | AM12: 0.57 | AN12: 5 | AO12: 1.3718395 | AP12: 91.494329 | AT12: 98.222034 | AX12: 98.222034 | BB12: 98.222034 | BC12: 0.05 | BD12: 55 | BE12: 0.19196513 | BF12: 57.611524 | BG12: -0.04 | BH12: 70 | BI12: -0.13494483 | BJ12: 44.632775 | BK12: -0.01 | BL12: 60 | BM12: 0.068237833 | BN12: 52.720184 | BO12: -0.2 | BP12: 77 | BQ12: -0.35622835 | BR12: 36.083478 | BS12: 0.13 | BT12: 44 | BU12: 0.45392433 | BV12: 67.505836 | BW12: 0.2 | BX12: 35 | BY12: 0.67235568 | BZ12: 74.932135 | CA12: 0 | CB12: 55 | CC12: 0.12068734 | CD12: 54.803066 | CE12: 0.99 | CF12: 11 | CG12: 1.2366868 | CH12: 89.18983 | CI12: 1.26 | CJ12: 4 | CK12: 1.9949125 | CL12: 97.697379 | CM12: 1.31 | CN12: 5 | CO12: 1.7417026 | CP12: 95.921975 | CQ12: 23.3 | CR12: 34 | CS12: 0.58955415 | CT12: 72.22552 | CU12: 24.2 | CV12: 6 | CW12: 1.5437842 | CX12: 93.867969 | CY12: 24.6 | CZ12: 3 | DA12: 1.5529158 | DB12: 93.977837 | DC12: 90.6 | DD12: 1 | DE12: 2.1216141 | DF12: 98.306492 | DG12: 90.4 | DH12: 2 | DI12: 2.495815 | DJ12: 99.371659 | DK12: 89.5 | DL12: 2 | DM12: 2.2966698 | DN12: 98.918119 | DQ12: 0 | DT12: 0 | DW12: 0 | DX12: #N/A | DY12: #N/A | DZ12: #N/A | EA12: #N/A | EB12: #N/A | EH12: -0.5 | EI12: #DIV/0! | EJ12: 0 | EK12: 0 | EL12: #DIV/0! | EM12: 0 | EN12: 0 | EO12: #DIV/0! | EP12: 0 | EQ12: 10 | ER12: 2.5 | ES12: #DIV/0! | ET12: 0 | EU12: 0 | EV12: 1.18 | EW12: 1.2684985 | EX12: 1.2684985 | EY12: 89.769001 | EZ12: 0 | FA12: #DIV/0! | FB12: #DIV/0! | FC12: 30 | FD12: 34/46 | FE12: 49 | FH12: 9 | FJ12: MC | FK12: 6 | FL12: 5 | FM12: 11 | FN12: 22 | FO12: 46 | FP12: 0.73913043 | FQ12: 34 | FR12: 0.97940738 | FS12: 83.631063 | FT12: 0.5 | FU12: 1.7434884 | FV12: 95.937583 | FW12: 0.2826087 | FX12: 2.3416805 | FY12: 99.040143 | FZ12: 0.15217391 | GA12: 1.8425321 | GB12: 96.730132 | GC12: 1.4335276 | GD12: 0.25 | GE12: 0.84176381 | GF12: 1.212657 | GG12: 88.736951 | GH12: 50 | GI12: 1.2479207 | GJ12: 0.5 | GK12: 0.87396036 | GL12: 1.649279 | GM12: 95.045476 | GN12: 92 | GO12: 0.82541344 | GP12: 0.22 | GQ12: 0.52270672 | GR12: 1.0945101 | GS12: 86.313435 | GT12: 157 | GU12: 6.4516129 | GV12: 13 | GW12: 13 | GX12: 0.0462 | GY12: 0.19375 | GZ12: 0.32945 | HA12: 40 | HB12: 475 | HC12: 210 | HD12: 0.021809756 | HE12: 0.13814565 | HF12: 0.16588226 | HH12: =IFERROR(RANK(HI12,HI$4:HI$1100),"") -> 4 | HI12: =IFERROR(((J12*G$1)+(N12*K$1)+(R12*O$1)+(V12*S$1)+(Z12*W$1)+(AD12*AA$1)+(AH12*AE$1)+(AL12*AI$1)+(AP12*AM$1)+(AT12*AQ$1)+(AX12*AU$1)+(BB12*AY$1)+(BF12*BC$1)+(BJ12*BG$1)+(BN12*BK$1)+(BR12*BO$1)+(BV12*BS$1)+(BZ12*BW$1)+(CD12*CA$1)+(CH12*CE$1)+(CL12*CI$1)+(CP12*CM$1)+(CT12*CQ$1)+(CX12*CU$1)+(DB12*CY$1)+(DF12*DC$1)+(DJ12*DG$1)+(DN12*DK$1)+(DQ12*DO$1)+(DT12*DR$1)+(DW12*DU$1)+(EU12*EU$1)+(EY12*EV$1)+(FC12*EZ$1)+(FS12*FP$1)+(GB12*FZ$1)+(FY12*FW$1)+(FV12*FT$1)+(GG12*GE$1)+(GM12*GK$1)+(GS12*GQ$1)+(GU12*GU$1))*(1+HG12),"") -> 80.302176 | HJ12: 8800 | HK12: 0.1012 | HL12: =IFERROR(GV12-HH12,"") -> 9 | HM12: =IFERROR(HI12/(HJ12/1000),0) -> 9.1252473 | HN12: 10500 | HO12: 0.1993 | HP12: =GW12-HH12 -> 9 | HQ12: =HI12/(HN12/1000) -> 7.6478263
A13: Max McGreevy | B13: 100 | C13: 850 | D13: 350 | E13: 79 | F13: 61.71875 | G13: -0.14 | H13: 71 | I13: -0.28210792 | J13: 38.893038 | K13: 0.02 | L13: 56 | M13: 0.19873556 | N13: 57.87652 | O13: 0.21 | P13: 32 | Q13: 0.739018 | R13: 77.005197 | S13: 85.9 | T13: 30 | U13: 0.75210105 | V13: 77.400485 | W13: 83.3 | X13: 34 | Y13: 0.60433215 | Z13: 72.718858 | AA13: 85.4 | AB13: 11 | AC13: 1.2556671 | AD13: 89.538166 | AE13: 0.22 | AF13: 40 | AG13: 0.43270231 | AH13: 66.738447 | AI13: 0.35 | AJ13: 22 | AK13: 0.89525414 | AL13: 81.467437 | AM13: 0.26 | AN13: 25 | AO13: 0.72279596 | AP13: 76.509738 | AT13: 81.467437 | AX13: 81.467437 | BB13: 81.467437 | BC13: 0.12 | BD13: 36 | BE13: 0.44282896 | BF13: 67.105527 | BG13: 0.06 | BH13: 47 | BI13: 0.22602437 | BJ13: 58.940877 | BK13: 0.09 | BL13: 36 | BM13: 0.42808663 | BN13: 66.570598 | BO13: 0.05 | BP13: 52 | BQ13: 0.15743501 | BR13: 56.254899 | BS13: -0.26 | BT13: 84 | BU13: -0.55522671 | BV13: 28.93698 | BW13: -0.26 | BX13: 87 | BY13: -0.55571019 | BZ13: 28.920449 | CA13: -0.07 | CB13: 69 | CC13: 0.0063788233 | CD13: 50.254477 | CE13: 0.1 | CF13: 48 | CG13: 0.29075199 | CH13: 61.43795 | CI13: -0.12 | CJ13: 82 | CK13: -0.5361299 | CL13: 29.593439 | CM13: 0.33 | CN13: 29 | CO13: 0.60248294 | CP13: 72.657364 | CQ13: 22.2 | CR13: 53 | CS13: 0.13594343 | CT13: 55.4067 | CU13: 20 | CV13: 85 | CW13: -0.39740605 | CX13: 34.553403 | CY13: 22.5 | CZ13: 42 | DA13: 0.45237476 | DB13: 67.450049 | DC13: 84 | DD13: 79 | DE13: -0.30968823 | DF13: 37.839903 | DG13: 83.9 | DH13: 70 | DI13: -0.098131652 | DJ13: 46.091388 | DK13: 85.8 | DL13: 36 | DM13: 0.54066089 | DN13: 70.562933 | DQ13: 0 | DT13: 0 | DW13: 0 | DX13: #N/A | DY13: #N/A | DZ13: #N/A | EA13: #N/A | EB13: #N/A | EH13: -0.5 | EI13: #DIV/0! | EJ13: 0 | EK13: 0 | EL13: #DIV/0! | EM13: 0 | EN13: 0 | EO13: #DIV/0! | EP13: 0 | EQ13: 10 | ER13: 2.5 | ES13: #DIV/0! | ET13: 0 | EU13: 0 | EV13: 1.01 | EW13: 1.0349232 | EX13: 1.0349232 | EY13: 84.964761 | EZ13: 0 | FA13: #DIV/0! | FB13: #DIV/0! | FC13: 30 | FD13: 31/54 | FJ13: MC | FK13: MC | FL13: MC | FM13: 11 | FN13: MC | FO13: 54 | FP13: 0.57407407 | FQ13: 31 | FR13: 0.023772865 | FS13: 50.948311 | FT13: 0.31481481 | FU13: 0.30100277 | FV13: 61.829381 | FW13: 0.12962963 | FX13: 0.17904005 | FY13: 57.104687 | FZ13: 0.074074074 | GA13: 0.25881522 | GB13: 60.211109 | GC13: 0.11148384 | GD13: -0.02 | GE13: 0.045741918 | GF13: 0.27519765 | GG13: 60.84178 | GH13: 32 | GI13: 0.15761324 | GJ13: -0.05 | GK13: 0.053806619 | GL13: 0.44068728 | GM13: 67.02803 | GN13: 74 | GO13: 0.3789146 | GP13: 0.3 | GQ13: 0.3394573 | GR13: 0.79519512 | GS13: 78.674999 | GT13: 168 | GU13: 79.83871 | GV13: 53 | GW13: 57 | GX13: 0.0083 | GY13: 0.0548 | GZ13: 0.12095 | HA13: 100 | HB13: 850 | HC13: 350 | HD13: -0.0016009901 | HE13: 0.0051605263 | HF13: 0.0028944444 | HH13: =IFERROR(RANK(HI13,HI$4:HI$1100),"") -> 30 | HI13: =IFERROR(((J13*G$1)+(N13*K$1)+(R13*O$1)+(V13*S$1)+(Z13*W$1)+(AD13*AA$1)+(AH13*AE$1)+(AL13*AI$1)+(AP13*AM$1)+(AT13*AQ$1)+(AX13*AU$1)+(BB13*AY$1)+(BF13*BC$1)+(BJ13*BG$1)+(BN13*BK$1)+(BR13*BO$1)+(BV13*BS$1)+(BZ13*BW$1)+(CD13*CA$1)+(CH13*CE$1)+(CL13*CI$1)+(CP13*CM$1)+(CT13*CQ$1)+(CX13*CU$1)+(DB13*CY$1)+(DF13*DC$1)+(DJ13*DG$1)+(DN13*DK$1)+(DQ13*DO$1)+(DT13*DR$1)+(DW13*DU$1)+(EU13*EU$1)+(EY13*EV$1)+(FC13*EZ$1)+(FS13*FP$1)+(GB13*FZ$1)+(FY13*FW$1)+(FV13*FT$1)+(GG13*GE$1)+(GM13*GK$1)+(GS13*GQ$1)+(GU13*GU$1))*(1+HG13),"") -> 63.907738 | HJ13: 7000 | HK13: 0.0295 | HL13: =IFERROR(GV13-HH13,"") -> 23 | HM13: =IFERROR(HI13/(HJ13/1000),0) -> 9.1296768 | HN13: 8400 | HO13: 0.049 | HP13: =GW13-HH13 -> 27 | HQ13: =HI13/(HN13/1000) -> 7.608064
A14: Rico Hoey | B14: 66 | C14: 600 | D14: 250 | E14: 92 | F14: 71.875 | G14: 0.29 | H14: 33 | I14: 0.72980821 | J14: 76.724629 | K14: 0.47 | L14: 9 | M14: 1.3069518 | N14: 90.438546 | O14: 0.43 | P14: 9 | Q14: 1.3326227 | R14: 90.867217 | S14: 84.8 | T14: 46 | U14: 0.46615285 | V14: 67.944695 | W14: 84.1 | X14: 27 | Y14: 0.81634804 | Z14: 79.284945 | AA14: 83.6 | AB14: 30 | AC14: 0.71742073 | AD14: 76.344273 | AE14: 0.28 | AF14: 32 | AG14: 0.53952013 | AH14: 70.523599 | AI14: 0.05 | AJ14: 49 | AK14: 0.28168966 | AL14: 61.090926 | AM14: 0.22 | AN14: 33 | AO14: 0.63904841 | AP14: 73.860428 | AT14: 61.090926 | AX14: 61.090926 | BB14: 61.090926 | BC14: 0 | BD14: 64 | BE14: 0.012776681 | BF14: 50.509702 | BG14: -0.03 | BH14: 67 | BI14: -0.098847913 | BJ14: 46.062951 | BK14: -0.17 | BL14: 95 | BM14: -0.50752025 | BN14: 30.589492 | BO14: -0.39 | BP14: 87 | BQ14: -0.74661251 | BR14: 22.764875 | BS14: -0.09 | BT14: 66 | BU14: -0.11534036 | BV14: 45.408768 | BW14: -0.27 | BX14: 90 | BY14: -0.58240727 | BZ14: 28.014619 | CA14: -0.56 | CB14: 107 | CC14: -0.79378077 | CD14: 21.366154 | CE14: 0.52 | CF14: 25 | CG14: 0.73714817 | CH14: 76.948388 | CI14: 0.95 | CJ14: 13 | CK14: 1.426345 | CL14: 92.311561 | CM14: 1.16 | CN14: 7 | CO14: 1.5673323 | CP14: 94.148148 | CQ14: 23.1 | CR14: 38 | CS14: 0.50707947 | CT14: 69.395047 | CU14: 22.5 | CV14: 23 | CW14: 0.75806435 | CX14: 77.579377 | CY14: 23.4 | CZ14: 18 | DA14: 0.92403519 | DB14: 82.2266 | DC14: 85.2 | DD14: 55 | DE14: 0.13236674 | DF14: 55.265289 | DG14: 85.1 | DH14: 47 | DI14: 0.38075081 | DJ14: 64.830592 | DK14: 85.4 | DL14: 46 | DM14: 0.3508221 | DN14: 63.713909 | DQ14: 0 | DT14: 0 | DW14: 0 | DX14: #N/A | DY14: #N/A | DZ14: #N/A | EA14: #N/A | EB14: #N/A | EH14: -0.5 | EI14: #DIV/0! | EJ14: 0 | EK14: 0 | EL14: #DIV/0! | EM14: 0 | EN14: 0 | EO14: #DIV/0! | EP14: 0 | EQ14: 10 | ER14: 2.5 | ES14: #DIV/0! | ET14: 0 | EU14: 0 | EV14: 1.07 | EW14: 1.1173615 | EX14: 1.1173615 | EY14: 86.808011 | EZ14: 0 | FA14: #DIV/0! | FB14: #DIV/0! | FC14: 30 | FD14: 40/52 | FJ14: 25 | FK14: 15 | FL14: 62 | FM14: 67 | FN14: 49 | FO14: 52 | FP14: 0.76923077 | FQ14: 40 | FR14: 1.1536807 | FS14: 87.568445 | FT14: 0.46153846 | FU14: 1.4438952 | FV14: 92.561578 | FW14: 0.17307692 | FX14: 0.79324744 | FY14: 78.618316 | FZ14: 0.038461538 | GA14: -0.46333957 | GB14: 32.156049 | GC14: 0.5240539 | GD14: -0.22 | GE14: 0.15202695 | GF14: 0.40036745 | GG14: 65.555705 | GH14: 36 | GI14: -0.011571519 | GJ14: 0.19 | GK14: 0.08921424 | GL14: 0.49286453 | GM14: 68.894584 | GN14: 81 | GO14: 0.37388462 | GP14: 0.27 | GQ14: 0.32194231 | GR14: 0.76658658 | GS14: 77.833632 | GT14: 179 | GU14: 67.741935 | GV14: 27 | GW14: 29 | GX14: 0.0225 | GY14: 0.1101 | GZ14: 0.2091 | HA14: 66 | HB14: 600 | HC14: 250 | HD14: 0.0075746269 | HE14: 0.051957143 | HF14: 0.050828571 | HH14: =IFERROR(RANK(HI14,HI$4:HI$1100),"") -> 16 | HI14: =IFERROR(((J14*G$1)+(N14*K$1)+(R14*O$1)+(V14*S$1)+(Z14*W$1)+(AD14*AA$1)+(AH14*AE$1)+(AL14*AI$1)+(AP14*AM$1)+(AT14*AQ$1)+(AX14*AU$1)+(BB14*AY$1)+(BF14*BC$1)+(BJ14*BG$1)+(BN14*BK$1)+(BR14*BO$1)+(BV14*BS$1)+(BZ14*BW$1)+(CD14*CA$1)+(CH14*CE$1)+(CL14*CI$1)+(CP14*CM$1)+(CT14*CQ$1)+(CX14*CU$1)+(DB14*CY$1)+(DF14*DC$1)+(DJ14*DG$1)+(DN14*DK$1)+(DQ14*DO$1)+(DT14*DR$1)+(DW14*DU$1)+(EU14*EU$1)+(EY14*EV$1)+(FC14*EZ$1)+(FS14*FP$1)+(GB14*FZ$1)+(FY14*FW$1)+(FV14*FT$1)+(GG14*GE$1)+(GM14*GK$1)+(GS14*GQ$1)+(GU14*GU$1))*(1+HG14),"") -> 70.499583 | HJ14: 7700 | HK14: 0.1328 | HL14: =IFERROR(GV14-HH14,"") -> 11 | HM14: =IFERROR(HI14/(HJ14/1000),0) -> 9.15579 | HN14: 9400 | HO14: 0.1572 | HP14: =GW14-HH14 -> 13 | HQ14: =HI14/(HN14/1000) -> 7.4999557
A15: Jackson Koivun | B15: 14 | C15: 180 | D15: -120 | E15: 128 | F15: 100 | G15: 0.46 | H15: 11 | I15: 1.1298681 | J15: 87.073409 | K15: 0.46 | L15: 10 | M15: 1.2823248 | N15: 90.013563 | O15: 0.43 | P15: 9 | Q15: 1.3326227 | R15: 90.867217 | S15: 86.8 | T15: 20 | U15: 0.98605867 | V15: 83.794784 | W15: 86.8 | X15: 6 | Y15: 1.5319016 | Z15: 93.722665 | AA15: 85.5 | AB15: 9 | AC15: 1.2855697 | AD15: 90.070336 | AE15: 0.59 | AF15: 17 | AG15: 1.0914122 | AH15: 86.245422 | AI15: 0.59 | AJ15: 5 | AK15: 1.3861057 | AL15: 91.714269 | AM15: 0.76 | AN15: 2 | AO15: 1.7696403 | AP15: 96.160646 | AT15: 91.714269 | AX15: 91.714269 | BB15: 91.714269 | BC15: 0.22 | BD15: 17 | BE15: 0.80120586 | BF15: 78.849376 | BG15: 0.22 | BH15: 18 | BI15: 0.80357509 | BJ15: 78.917879 | BK15: 0.17 | BL15: 21 | BM15: 0.71596567 | BN15: 76.299373 | BO15: 0.14 | BP15: 47 | BQ15: 0.34235382 | BR15: 63.395768 | BS15: 0.14 | BT15: 42 | BU15: 0.4798 | BV15: 68.431519 | BW15: 0.31 | BX15: 22 | BY15: 0.9660236 | BZ15: 83.298381 | CA15: 0.91 | CB15: 4 | CC15: 1.606698 | CD15: 94.593968 | CE15: 1.64 | CF15: 3 | CG15: 1.927538 | CH15: 97.304369 | CI15: 1.64 | CJ15: 2 | CK15: 2.6918663 | CL15: 99.644733 | CM15: 1.71 | CN15: 1 | CO15: 2.2066902 | CP15: 98.633215 | CQ15: 22.9 | CR15: 42 | CS15: 0.4246048 | CT15: 66.44376 | CU15: 22.9 | CV15: 19 | CW15: 0.94293962 | CX15: 82.714411 | CY15: 24.1 | CZ15: 5 | DA15: 1.2908822 | DB15: 90.162773 | DC15: 88.5 | DD15: 8 | DE15: 1.3480179 | DF15: 91.117369 | DG15: 88.5 | DH15: 4 | DI15: 1.7375845 | DJ15: 95.885797 | DK15: 88.3 | DL15: 3 | DM15: 1.7271534 | DN15: 95.792994 | DQ15: 0 | DT15: 0 | DW15: 0 | DX15: #N/A | DY15: #N/A | DZ15: #N/A | EA15: #N/A | EB15: #N/A | EH15: -0.5 | EI15: #DIV/0! | EJ15: 0 | EK15: 0 | EL15: #DIV/0! | EM15: 0 | EN15: 0 | EO15: #DIV/0! | EP15: 0 | EQ15: 10 | ER15: 2.5 | ES15: #DIV/0! | ET15: 0 | EU15: 0 | EV15: 1.64 | EW15: 1.9005258 | EX15: 1.9005258 | EY15: 97.131792 | EZ15: 0 | FA15: #DIV/0! | FB15: #DIV/0! | FC15: 30 | FD15: 12/14 | FI15: 24 | FJ15: 29 | FK15: 31 | FL15: 1 | FN15: 10 | FO15: 14 | FP15: 0.85714286 | FQ15: 12 | FR15: 1.6626694 | FS15: 95.181069 | FT15: 0.64285714 | FU15: 2.8562631 | FV15: 99.78567 | FW15: 0.42857143 | FX15: 4.4051321 | FY15: 99.999471 | FZ15: 0.28571429 | GA15: 4.550478 | GB15: 99.999732 | GC15: 1.4558505 | GD15: 1.4 | GE15: 1.4279252 | GF15: 1.9029679 | GG15: 97.147763 | GH15: 26 | GI15: 1.4558505 | GJ15: 1.4 | GK15: 1.4279252 | GL15: 2.4656106 | GM15: 99.3161 | GN15: 26 | GO15: 1.4711562 | GP15: 1.63 | GQ15: 1.5505781 | GR15: 2.7734096 | GS15: 99.722639 | GT15: 52 | GU15: 61.290323 | GV15: 1 | GW15: 1 | GX15: 0.0864 | GY15: 0.30565 | GZ15: 0.48105 | HA15: 14 | HB15: 180 | HC15: -120 | HD15: 0.019733333 | HE15: 0.088192857 | HF15: 0.072777273 | HH15: =IFERROR(RANK(HI15,HI$4:HI$1100),"") -> 1 | HI15: =IFERROR(((J15*G$1)+(N15*K$1)+(R15*O$1)+(V15*S$1)+(Z15*W$1)+(AD15*AA$1)+(AH15*AE$1)+(AL15*AI$1)+(AP15*AM$1)+(AT15*AQ$1)+(AX15*AU$1)+(BB15*AY$1)+(BF15*BC$1)+(BJ15*BG$1)+(BN15*BK$1)+(BR15*BO$1)+(BV15*BS$1)+(BZ15*BW$1)+(CD15*CA$1)+(CH15*CE$1)+(CL15*CI$1)+(CP15*CM$1)+(CT15*CQ$1)+(CX15*CU$1)+(DB15*CY$1)+(DF15*DC$1)+(DJ15*DG$1)+(DN15*DK$1)+(DQ15*DO$1)+(DT15*DR$1)+(DW15*DU$1)+(EU15*EU$1)+(EY15*EV$1)+(FC15*EZ$1)+(FS15*FP$1)+(GB15*FZ$1)+(FY15*FW$1)+(FV15*FT$1)+(GG15*GE$1)+(GM15*GK$1)+(GS15*GQ$1)+(GU15*GU$1))*(1+HG15),"") -> 89.401135 | HJ15: 10500 | HK15: 0.1396 | HL15: =IFERROR(GV15-HH15,"") -> 0 | HM15: =IFERROR(HI15/(HJ15/1000),0) -> 8.5143938 | HN15: 12000 | HO15: 0.2771 | HP15: =GW15-HH15 -> 0 | HQ15: =HI15/(HN15/1000) -> 7.4500946
A16: Doug Ghim | B16: 28 | C16: 300 | D16: 137 | E16: 124 | F16: 96.875 | G16: 0.67 | H16: 5 | I16: 1.6240597 | J16: 94.781846 | K16: 0.65 | L16: 2 | M16: 1.7502383 | N16: 95.99614 | O16: 0.56 | P16: 4 | Q16: 1.6833891 | R16: 95.38501 | S16: 86 | T16: 28 | U16: 0.77809634 | V16: 78.174389 | W16: 84.5 | X16: 22 | Y16: 0.92235598 | Z16: 82.182854 | AA16: 84.2 | AB16: 21 | AC16: 0.8968362 | AD16: 81.509684 | AE16: 0.34 | AF16: 29 | AG16: 0.64633794 | AH16: 74.096974 | AI16: 0.31 | AJ16: 24 | AK16: 0.81344554 | AL16: 79.201867 | AM16: 0.26 | AN16: 25 | AO16: 0.72279596 | AP16: 76.509738 | AT16: 79.201867 | AX16: 79.201867 | BB16: 79.201867 | BC16: 0.22 | BD16: 17 | BE16: 0.80120586 | BF16: 78.849376 | BG16: 0.26 | BH16: 15 | BI16: 0.94796278 | BJ16: 82.84258 | BK16: 0.21 | BL16: 19 | BM16: 0.85990519 | BN16: 80.507935 | BO16: 0.28 | BP16: 37 | BQ16: 0.6300053 | BR16: 73.565444 | BS16: -0.1 | BT16: 69 | BU16: -0.14121602 | BV16: 44.384964 | BW16: -0.16 | BX16: 76 | BY16: -0.28873935 | BZ16: 38.639042 | CA16: 0.07 | CB16: 50 | CC16: 0.23499585 | CD16: 59.289402 | CE16: 1.3 | CF16: 8 | CG16: 1.5661696 | CH16: 94.134555 | CI16: 1 | CJ16: 12 | CK16: 1.5180495 | CL16: 93.549904 | CM16: 1.03 | CN16: 9 | CO16: 1.4162113 | CP16: 92.164317 | CQ16: 24.4 | CR16: 20 | CS16: 1.0431649 | CT16: 85.156403 | CU16: 23.1 | CV16: 16 | CW16: 1.0353773 | CX16: 84.975362 | CY16: 24 | CZ16: 7 | DA16: 1.2384755 | DB16: 89.223009 | DC16: 89.4 | DD16: 3 | DE16: 1.6795592 | DF16: 95.347844 | DG16: 88.4 | DH16: 5 | DI16: 1.6976776 | DJ16: 95.521568 | DK16: 87.8 | DL16: 5 | DM16: 1.4898549 | DN16: 93.18688 | DQ16: 0 | DT16: 0 | DW16: 0 | DX16: #N/A | DY16: #N/A | DZ16: #N/A | EA16: #N/A | EB16: #N/A | EH16: -0.5 | EI16: #DIV/0! | EJ16: 0 | EK16: 0 | EL16: #DIV/0! | EM16: 0 | EN16: 0 | EO16: #DIV/0! | EP16: 0 | EQ16: 10 | ER16: 2.5 | ES16: #DIV/0! | ET16: 0 | EU16: 0 | EV16: 0.85 | EW16: 0.81508762 | EX16: 0.81508762 | EY16: 79.248892 | EZ16: 0 | FA16: #DIV/0! | FB16: #DIV/0! | FC16: 30 | FD16: 32/44 | FJ16: 19 | FK16: 15 | FL16: MC | FN16: MC | FO16: 44 | FP16: 0.72727273 | FQ16: 32 | FR16: 0.91075426 | FS16: 81.878757 | FT16: 0.45454545 | FU16: 1.3894238 | FV16: 91.764804 | FW16: 0.090909091 | FX16: -0.36834597 | FY16: 35.630764 | FZ16: 0.068181818 | GA16: 0.13933143 | GB16: 55.540587 | GC16: 1.2895187 | GD16: 1.36 | GE16: 1.3247594 | GF16: 1.7814714 | GG16: 96.258227 | GH16: 28 | GI16: 0.86891172 | GJ16: 0.88 | GK16: 0.87445586 | GL16: 1.6500092 | GM16: 95.052948 | GN16: 63 | GO16: 0.54979728 | GP16: 0.46 | GQ16: 0.50489864 | GR16: 1.0654229 | GS16: 85.665769 | GT16: 151 | GU16: 69.354839 | GV16: 3 | GW16: 6 | GX16: 0.0521 | GY16: 0.2183 | GZ16: 0.371 | HA16: 28 | HB16: 300 | HC16: 137 | HD16: 0.017617241 | HE16: 0.096 | HF16: 0.10196793 | HH16: =IFERROR(RANK(HI16,HI$4:HI$1100),"") -> 2 | HI16: =IFERROR(((J16*G$1)+(N16*K$1)+(R16*O$1)+(V16*S$1)+(Z16*W$1)+(AD16*AA$1)+(AH16*AE$1)+(AL16*AI$1)+(AP16*AM$1)+(AT16*AQ$1)+(AX16*AU$1)+(BB16*AY$1)+(BF16*BC$1)+(BJ16*BG$1)+(BN16*BK$1)+(BR16*BO$1)+(BV16*BS$1)+(BZ16*BW$1)+(CD16*CA$1)+(CH16*CE$1)+(CL16*CI$1)+(CP16*CM$1)+(CT16*CQ$1)+(CX16*CU$1)+(DB16*CY$1)+(DF16*DC$1)+(DJ16*DG$1)+(DN16*DK$1)+(DQ16*DO$1)+(DT16*DR$1)+(DW16*DU$1)+(EU16*EU$1)+(EY16*EV$1)+(FC16*EZ$1)+(FS16*FP$1)+(GB16*FZ$1)+(FY16*FW$1)+(FV16*FT$1)+(GG16*GE$1)+(GM16*GK$1)+(GS16*GQ$1)+(GU16*GU$1))*(1+HG16),"") -> 83.153901 | HJ16: 10000 | HK16: 0.1687 | HL16: =IFERROR(GV16-HH16,"") -> 1 | HM16: =IFERROR(HI16/(HJ16/1000),0) -> 8.3153901 | HN16: 11200 | HO16: 0.1151 | HP16: =GW16-HH16 -> 4 | HQ16: =HI16/(HN16/1000) -> 7.4244554
A17: Patrick Fishburn | B17: 100 | C17: 800 | D17: 333 | E17: 79 | F17: 61.71875 | G17: 0.5 | H17: 9 | I17: 1.2239998 | J17: 88.952385 | K17: 0.37 | L17: 17 | M17: 1.0606815 | N17: 85.558267 | O17: 0.27 | P17: 24 | Q17: 0.90091019 | R17: 81.618196 | S17: 85.7 | T17: 31 | U17: 0.70011047 | V17: 75.807084 | W17: 82.3 | X17: 46 | Y17: 0.3393123 | Z17: 63.281276 | AA17: 82.9 | AB17: 40 | AC17: 0.50810268 | AD17: 69.430933 | AE17: -0.09 | AF17: 66 | AG17: -0.11918975 | AH17: 45.256251 | AI17: 0 | AJ17: 56 | AK17: 0.17942891 | AL17: 57.119953 | AM17: -0.01 | AN17: 62 | AO17: 0.15750001 | AP17: 56.25746 | AT17: 57.119953 | AX17: 57.119953 | BB17: 57.119953 | BC17: -0.01 | BD17: 67 | BE17: -0.023061009 | BF17: 49.08008 | BG17: -0.09 | BH17: 83 | BI17: -0.31542943 | BJ17: 37.621781 | BK17: -0.1 | BL17: 80 | BM17: -0.25562609 | BN17: 39.911979 | BO17: 0.05 | BP17: 52 | BQ17: 0.15743501 | BR17: 56.254899 | BS17: -0.05 | BT17: 61 | BU17: -0.011837685 | BV17: 49.527756 | BW17: 0.07 | BX17: 51 | BY17: 0.32529358 | BZ17: 62.752056 | CA17: 0.37 | CB17: 28 | CC17: 0.72488948 | CD17: 76.574008 | CE17: 0.63 | CF17: 21 | CG17: 0.85406146 | CH17: 80.346453 | CI17: 0.8 | CJ17: 17 | CK17: 1.1512317 | CL17: 87.518154 | CM17: 0.1 | CN17: 47 | CO17: 0.33511506 | CP17: 63.123085 | CQ17: 22.6 | CR17: 50 | CS17: 0.30089278 | CT17: 61.825187 | CU17: 21.1 | CV17: 54 | CW17: 0.11100093 | CX17: 54.419219 | CY17: 20.9 | CZ17: 89 | DA17: -0.38613267 | DB17: 34.969921 | DC17: 87.4 | DD17: 20 | DE17: 0.94280086 | DF17: 82.710862 | DG17: 86.2 | DH17: 17 | DI17: 0.8197264 | DJ17: 79.381395 | DK17: 85.9 | DL17: 33 | DM17: 0.58812059 | DN17: 72.177432 | DQ17: 0 | DT17: 0 | DW17: 0 | DX17: #N/A | DY17: #N/A | DZ17: #N/A | EA17: #N/A | EB17: #N/A | EH17: -0.5 | EI17: #DIV/0! | EJ17: 0 | EK17: 0 | EL17: #DIV/0! | EM17: 0 | EN17: 0 | EO17: #DIV/0! | EP17: 0 | EQ17: 10 | ER17: 2.5 | ES17: #DIV/0! | ET17: 0 | EU17: 0 | EV17: 0.47 | EW17: 0.29297813 | EX17: 0.29297813 | EY17: 61.523057 | EZ17: 0 | FA17: #DIV/0! | FB17: #DIV/0! | FC17: 30 | FD17: 27/46 | FJ17: 49 | FK17: 50 | FL17: 16 | FM17: 42 | FN17: MC | FO17: 46 | FP17: 0.58695652 | FQ17: 27 | FR17: 0.098358974 | FS17: 53.917637 | FT17: 0.2173913 | FU17: -0.45787011 | FV17: 32.352288 | FW17: 0.086956522 | FX17: -0.4242228 | FY17: 33.570167 | FZ17: 0.065217391 | GA17: 0.079218462 | GB17: 53.157057 | GC17: 0.39849238 | GD17: 0.11 | GE17: 0.25424619 | GF17: 0.52074904 | GG17: 69.87292 | GH17: 34 | GI17: -0.10022869 | GJ17: -0.04 | GK17: -0.070114345 | GL17: 0.25807536 | GM17: 60.182563 | GN17: 59 | GO17: 0.19067119 | GP17: -0.36 | GQ17: -0.084664406 | GR17: 0.10244532 | GS17: 54.07984 | GT17: 148 | GU17: 51.612903 | GV17: 48 | GW17: 57 | GX17: 0.00825 | GY17: 0.04855 | GZ17: 0.10915 | HA17: 100 | HB17: 800 | HC17: 333 | HD17: -0.0016509901 | HE17: -0.013072222 | HF17: -0.025488915 | HH17: =IFERROR(RANK(HI17,HI$4:HI$1100),"") -> 34 | HI17: =IFERROR(((J17*G$1)+(N17*K$1)+(R17*O$1)+(V17*S$1)+(Z17*W$1)+(AD17*AA$1)+(AH17*AE$1)+(AL17*AI$1)+(AP17*AM$1)+(AT17*AQ$1)+(AX17*AU$1)+(BB17*AY$1)+(BF17*BC$1)+(BJ17*BG$1)+(BN17*BK$1)+(BR17*BO$1)+(BV17*BS$1)+(BZ17*BW$1)+(CD17*CA$1)+(CH17*CE$1)+(CL17*CI$1)+(CP17*CM$1)+(CT17*CQ$1)+(CX17*CU$1)+(DB17*CY$1)+(DF17*DC$1)+(DJ17*DG$1)+(DN17*DK$1)+(DQ17*DO$1)+(DT17*DR$1)+(DW17*DU$1)+(EU17*EU$1)+(EY17*EV$1)+(FC17*EZ$1)+(FS17*FP$1)+(GB17*FZ$1)+(FY17*FW$1)+(FV17*FT$1)+(GG17*GE$1)+(GM17*GK$1)+(GS17*GQ$1)+(GU17*GU$1))*(1+HG17),"") -> 62.048711 | HJ17: 7100 | HK17: 0.0448 | HL17: =IFERROR(GV17-HH17,"") -> 14 | HM17: =IFERROR(HI17/(HJ17/1000),0) -> 8.739255 | HN17: 8400 | HO17: 0.0387 | HP17: =GW17-HH17 -> 23 | HQ17: =HI17/(HN17/1000) -> 7.3867513
A18: Kris Ventura | B18: 66 | C18: 650 | D18: 275 | E18: 92 | F18: 71.875 | G18: 0.76 | H18: 3 | I18: 1.8358561 | J18: 96.681053 | K18: 0.65 | L18: 2 | M18: 1.7502383 | N18: 95.99614 | O18: 0.53 | P18: 5 | Q18: 1.602443 | R18: 94.547116 | S18: 86.9 | T18: 17 | U18: 1.012054 | V18: 84.424387 | W18: 85 | X18: 16 | Y18: 1.0548659 | Z18: 85.425667 | AA18: 84.9 | AB18: 15 | AC18: 1.1061542 | AD18: 86.567012 | AE18: 0.13 | AF18: 48 | AG18: 0.27247558 | AH18: 60.737182 | AI18: -0.08 | AJ18: 65 | AK18: 0.015811717 | AL18: 50.63077 | AM18: -0.15 | AN18: 79 | AO18: -0.13561641 | AP18: 44.606227 | AT18: 50.63077 | AX18: 50.63077 | BB18: 50.63077 | BC18: -0.09 | BD18: 83 | BE18: -0.30976253 | BF18: 37.837077 | BG18: -0.24 | BH18: 105 | BI18: -0.85688324 | BJ18: 19.575471 | BK18: -0.19 | BL18: 97 | BM18: -0.57949001 | BN18: 28.112929 | BO18: 0.07 | BP18: 51 | BQ18: 0.19852808 | BR18: 57.868404 | BS18: -0.14 | BT18: 73 | BU18: -0.24471869 | BV18: 40.333713 | BW18: 0.16 | BX18: 39 | BY18: 0.56556734 | BZ18: 71.415603 | CA18: -0.23 | CB18: 82 | CC18: -0.25489778 | CD18: 39.940103 | CE18: 1.29 | CF18: 9 | CG18: 1.5555412 | CH18: 94.009138 | CI18: 0.91 | CJ18: 14 | CK18: 1.3529815 | CL18: 91.196923 | CM18: 0.94 | CN18: 13 | CO18: 1.3115891 | CP18: 90.517059 | CQ18: 23.8 | CR18: 26 | CS18: 0.79574084 | CT18: 78.690866 | CU18: 21.5 | CV18: 48 | CW18: 0.29587619 | CX18: 61.633768 | CY18: 22.9 | CZ18: 27 | DA18: 0.66200161 | DB18: 74.601491 | DC18: 87.5 | DD18: 16 | DE18: 0.97963878 | DF18: 83.636777 | DG18: 85.6 | DH18: 31 | DI18: 0.58028517 | DJ18: 71.913884 | DK18: 87.1 | DL18: 10 | DM18: 1.157637 | DN18: 87.649389 | DQ18: 0 | DT18: 0 | DW18: 0 | DX18: #N/A | DY18: #N/A | DZ18: #N/A | EA18: #N/A | EB18: #N/A | EH18: -0.5 | EI18: #DIV/0! | EJ18: 0 | EK18: 0 | EL18: #DIV/0! | EM18: 0 | EN18: 0 | EO18: #DIV/0! | EP18: 0 | EQ18: 10 | ER18: 2.5 | ES18: #DIV/0! | ET18: 0 | EU18: 0 | EV18: 0.87 | EW18: 0.84256707 | EX18: 0.84256707 | EY18: 80.026469 | EZ18: 0 | FA18: #DIV/0! | FB18: #DIV/0! | FC18: 30 | FD18: 20/40 | FO18: 40 | FP18: 0.5 | FQ18: 20 | FR18: -0.40509726 | FS18: 34.270301 | FT18: 0.325 | FU18: 0.38033949 | FV18: 64.815329 | FW18: 0.075 | FX18: -0.59325022 | FY18: 27.650685 | FZ18: 0.05 | GA18: -0.22936142 | GB18: 40.929401 | GC18: -0.78196609 | GD18: 0.48 | GE18: -0.15098305 | GF18: 0.043518507 | GG18: 51.735589 | GH18: 8 | GI18: -0.22005586 | GJ18: 0.04 | GK18: -0.090027929 | GL18: 0.22873038 | GM18: 59.046076 | GN18: 31 | GO18: 0.27255679 | GP18: 0.14 | GQ18: 0.2062784 | GR18: 0.57766403 | GS18: 71.825451 | GT18: 121 | GU18: 45.16129 | GV18: 48 | GW18: 43 | GX18: 0.01335 | GY18: 0.07555 | GZ18: 0.15045 | HA18: 66 | HB18: 650 | HC18: 275 | HD18: -0.0015753731 | HE18: 0.0037833333 | HF18: -0.013316667 | HH18: =IFERROR(RANK(HI18,HI$4:HI$1100),"") -> 25 | HI18: =IFERROR(((J18*G$1)+(N18*K$1)+(R18*O$1)+(V18*S$1)+(Z18*W$1)+(AD18*AA$1)+(AH18*AE$1)+(AL18*AI$1)+(AP18*AM$1)+(AT18*AQ$1)+(AX18*AU$1)+(BB18*AY$1)+(BF18*BC$1)+(BJ18*BG$1)+(BN18*BK$1)+(BR18*BO$1)+(BV18*BS$1)+(BZ18*BW$1)+(CD18*CA$1)+(CH18*CE$1)+(CL18*CI$1)+(CP18*CM$1)+(CT18*CQ$1)+(CX18*CU$1)+(DB18*CY$1)+(DF18*DC$1)+(DJ18*DG$1)+(DN18*DK$1)+(DQ18*DO$1)+(DT18*DR$1)+(DW18*DU$1)+(EU18*EU$1)+(EY18*EV$1)+(FC18*EZ$1)+(FS18*FP$1)+(GB18*FZ$1)+(FY18*FW$1)+(FV18*FT$1)+(GG18*GE$1)+(GM18*GK$1)+(GS18*GQ$1)+(GU18*GU$1))*(1+HG18),"") -> 64.817174 | HJ18: 7100 | HK18: 0.0435 | HL18: =IFERROR(GV18-HH18,"") -> 23 | HM18: =IFERROR(HI18/(HJ18/1000),0) -> 9.1291795 | HN18: 8800 | HO18: 0.0582 | HP18: =GW18-HH18 -> 18 | HQ18: =HI18/(HN18/1000) -> 7.365588
